(dp1
S'output'
p2
S"<class 'shippo.error.APIConnectionError'> [Errno -3] Temporary failure in name resolution"
p3
sS'layer'
p4
S'/home/www-data/web2py/applications/reliefList/controllers/default.py'
p5
sS'code'
p6
S'<code object <module> at 0x7fbbac2be730, file "/home/www-data/web2py/applications/reliefList/controllers/default.py", line 2>'
p7
sS'snapshot'
p8
(dp9
sS'traceback'
p10
S'Traceback (most recent call last):\n  File "/home/www-data/web2py/gluon/restricted.py", line 219, in restricted\n    exec(ccode, environment)\n  File "/home/www-data/web2py/applications/reliefList/controllers/default.py", line 230, in <module>\n  File "/home/www-data/web2py/gluon/globals.py", line 414, in <lambda>\n    self._caller = lambda f: f()\n  File "/home/www-data/web2py/applications/reliefList/controllers/default.py", line 179, in deliveryChoice\n    async = False\n  File "/usr/local/lib/python2.7/dist-packages/shippo/resource.py", line 186, in create\n    response, api_key = requestor.request(\'post\', url, params)\n  File "/usr/local/lib/python2.7/dist-packages/shippo/api_requestor.py", line 69, in request\n    self._check_ssl_cert()\n  File "/usr/local/lib/python2.7/dist-packages/shippo/api_requestor.py", line 189, in _check_ssl_cert\n    raise error.APIConnectionError(e)\nAPIConnectionError: [Errno -3] Temporary failure in name resolution\n'
p11
s.